Workbook

Sheet COLLECTION PRICE
A1: Current prices - 2024
B2: Instalments | C2: ST | D2: PR | E2: ST+TK | F2: PR+TK | G2: PL1 | H2: Tkanivo placenty | I2: Tkanivo pupocnika | J2: Inflation rate 2024 | K2: FX rate
A3: SK | B3: 1 | C3: 690 | D3: 890 | E3: 990 | F3: 1190 | G3: 1490 | K3: 1
B4: 5 | C4: =+C3 -> 690 | D4: =+D3 -> 890 | E4: =+E3 -> 990 | F4: =+F3 -> 1190 | G4: =+G3 -> 1490
B5: 10 | C5: =+C4 -> 690 | D5: =+D4 -> 890 | E5: =+E4 -> 990 | F5: =+F4 -> 1190 | G5: =+G4 -> 1490
A6: RO | B6: 1 | C6: 2490 | D6: 3590 | E6: 3490 | F6: 4590 | G6: 9990 | K6: 5
B7: 3 | C7: 2739 | D7: 3771 | E7: 3789 | F7: 4821 | G7: 10490
B8: 12 | C8: 2988 | D8: 3948 | E8: 4092 | F8: 5052 | G8: 10990
A9: HU | B9: 1 | C9: 149000 | D9: 249000 | E9: 248000 | F9: 348000 | K9: 400
B10: 3 | C10: =+C9 -> 149000 | D10: =+D9 -> 249000 | E10: =+E9 -> 248000 | F10: =+F9 -> 348000 | G10: =+G9 -> 0
B11: 12 | C11: =+C10 -> 149000 | D11: =+D10 -> 249000 | E11: =+E10 -> 248000 | F11: =+F10 -> 348000 | G11: =+G10 -> 0
A12: CZ | B12: 1 | C12: 19900 | D12: 29900 | E12: 29900 | F12: 39900 | G12: 49900 | K12: 25
B13: 5 | C13: =+C12 -> 19900 | D13: =+D12 -> 29900 | E13: =+E12 -> 29900 | F13: =+F12 -> 39900 | G13: =+G12 -> 49900
B14: 10 | C14: =+C13 -> 19900 | D14: =+D13 -> 29900 | E14: =+E13 -> 29900 | F14: =+F13 -> 39900 | G14: =+G13 -> 49900
A15: AT | B15: 1 | C15: 1490 | D15: 1790 | E15: 2190 | F15: 2490 | K15: 1
B16: 4 | C16: =+C15 -> 1490 | D16: =+D15 -> 1790 | E16: =+E15 -> 2190 | F16: =+F15 -> 2490 | G16: =+G15 -> 0
B17: 8 | C17: =+C16 -> 1490 | D17: =+D16 -> 1790 | E17: =+E16 -> 2190 | F17: =+F16 -> 2490 | G17: =+G16 -> 0
A18: IT | B18: 1 | C18: 1090 | D18: 1290 | E18: 1390 | F18: 1590 | K18: 1
B19: 3 | C19: =+C18 -> 1090 | D19: =+D18 -> 1290 | E19: =+E18 -> 1390 | F19: =+F18 -> 1590 | G19: =+G18 -> 0
B20: 6 | C20: =+C19 -> 1090 | D20: =+D19 -> 1290 | E20: =+E19 -> 1390 | F20: =+F19 -> 1590 | G20: =+G19 -> 0
A23: New prices - local CCY - 2025 | J23: Instalment increase
B24: Instalments | C24: ST | D24: PR | E24: ST+TK | F24: PR+TK | G24: PL1 | H24: Tkanivo placenty | I24: Tkanivo pupocnika
A25: SK | B25: 1 | C25: 1400 | D25: 1600 | E25: 1800 | F25: 2100 | G25: 2500 | H25: 1600 | I25: 1200
B26: 3 | C26: =+C25*(1+$J26) -> 1400 | D26: =+D25*(1+$J26) -> 1600 | E26: =+E25*(1+$J26) -> 1800 | F26: =+F25*(1+$J26) -> 2100 | G26: =+G25*(1+$J26) -> 2500 | H26: =+H25*(1+$J26) -> 1600 | I26: =+I25*(1+$J26) -> 1200 | J26: 0
B27: 12 | C27: =+C25*(1+$J27) -> 1400 | D27: =+D25*(1+$J27) -> 1600 | E27: =+E25*(1+$J27) -> 1800 | F27: =+F25*(1+$J27) -> 2100 | G27: =+G25*(1+$J27) -> 2500 | H27: =+H25*(1+$J27) -> 1600 | I27: =+I25*(1+$J27) -> 1200 | J27: 0
A28: RO | B28: 1 | C28: =1400*$K$6 -> 7000 | D28: =1600*$K$6 -> 8000 | E28: =1800*$K$6 -> 9000 | F28: =2100*$K$6 -> 10500 | G28: =2500*$K$6 -> 12500 | H28: 8000 | I28: 3000
B29: 3 | C29: =+C28*(1+$J29) -> 7000 | D29: =+D28*(1+$J29) -> 8000 | E29: =+E28*(1+$J29) -> 9000 | F29: =+F28*(1+$J29) -> 10500 | G29: =+G28*(1+$J29) -> 12500 | H29: =+H28*(1+$J29) -> 8000 | I29: =+I28*(1+$J29) -> 3000 | J29: 0
B30: 12 | C30: =+C28*(1+$J30) -> 7000 | D30: =+D28*(1+$J30) -> 8000 | E30: =+E28*(1+$J30) -> 9000 | F30: =+F28*(1+$J30) -> 10500 | G30: =+G28*(1+$J30) -> 12500 | H30: =+H28*(1+$J30) -> 8000 | I30: =+I28*(1+$J30) -> 3000 | J30: 0
A31: HU | B31: 1 | C31: =1400*$K$9 -> 560000 | D31: =1600*$K$9 -> 640000 | E31: =1800*$K$9 -> 720000 | F31: =2100*$K$9 -> 840000 | I31: 240000
B32: 3 | C32: =+C31*(1+$J32) -> 560000 | D32: =+D31*(1+$J32) -> 640000 | E32: =+E31*(1+$J32) -> 720000 | F32: =+F31*(1+$J32) -> 840000 | I32: =+I31*(1+$J32) -> 240000 | J32: 0
B33: 12 | C33: =+C31*(1+$J33) -> 560000 | D33: =+D31*(1+$J33) -> 640000 | E33: =+E31*(1+$J33) -> 720000 | F33: =+F31*(1+$J33) -> 840000 | I33: =+I31*(1+$J33) -> 240000 | J33: 0
A34: CZ | B34: 1 | C34: =1400*$K$12 -> 35000 | D34: =1600*$K$12 -> 40000 | E34: =1800*$K$12 -> 45000 | F34: =2100*$K$12 -> 52500 | G34: =2500*$K$12 -> 62500 | H34: 40000 | I34: 30000
B35: 3 | C35: =+C34*(1+$J35) -> 35000 | D35: =+D34*(1+$J35) -> 40000 | E35: =+E34*(1+$J35) -> 45000 | F35: =+F34*(1+$J35) -> 52500 | G35: =+G34*(1+$J35) -> 62500 | H35: =+H34*(1+$J35) -> 40000 | I35: =+I34*(1+$J35) -> 30000 | J35: 0
B36: 12 | C36: =+C34*(1+$J36) -> 35000 | D36: =+D34*(1+$J36) -> 40000 | E36: =+E34*(1+$J36) -> 45000 | F36: =+F34*(1+$J36) -> 52500 | G36: =+G34*(1+$J36) -> 62500 | H36: =+H34*(1+$J36) -> 40000 | I36: =+I34*(1+$J36) -> 30000 | J36: 0
A37: AT | B37: 1 | C37: =+C15 -> 1490 | D37: =+D15 -> 1790 | E37: =+E15 -> 2190 | F37: =+F15 -> 2490 | G37: =+G15 -> 0 | H37: =+H15 -> 0 | I37: 1200
B38: 4 | C38: =+C37*(1+$J38) -> 1490 | D38: =+D37*(1+$J38) -> 1790 | E38: =+E37*(1+$J38) -> 2190 | F38: =+F37*(1+$J38) -> 2490 | G38: =+G37*(1+$J38) -> 0 | H38: =+H37*(1+$J38) -> 0 | I38: =+I37*(1+$J38) -> 1200 | J38: 0
B39: 8 | C39: =+C37*(1+$J39) -> 1490 | D39: =+D37*(1+$J39) -> 1790 | E39: =+E37*(1+$J39) -> 2190 | F39: =+F37*(1+$J39) -> 2490 | G39: =+G37*(1+$J39) -> 0 | H39: =+H37*(1+$J39) -> 0 | I39: =+I37*(1+$J39) -> 1200 | J39: 0
A40: IT | B40: 1 | C40: =+C18 -> 1090 | D40: =+D18 -> 1290 | E40: =+E18 -> 1390 | F40: =+F18 -> 1590 | G40: =+G18 -> 0 | H40: =+H18 -> 0 | I40: 300
B41: 3 | C41: =+C40*(1+$J41) -> 1090 | D41: =+D40*(1+$J41) -> 1290 | E41: =+E40*(1+$J41) -> 1390 | F41: =+F40*(1+$J41) -> 1590 | G41: =+G40*(1+$J41) -> 0 | H41: =+H40*(1+$J41) -> 0 | I41: =+I40*(1+$J41) -> 300 | J41: 0
B42: 6 | C42: =+C40*(1+$J42) -> 1090 | D42: =+D40*(1+$J42) -> 1290 | E42: =+E40*(1+$J42) -> 1390 | F42: =+F40*(1+$J42) -> 1590 | G42: =+G40*(1+$J42) -> 0 | H42: =+H40*(1+$J42) -> 0 | I42: =+I40*(1+$J42) -> 300 | J42: 0
...

Sheet STORAGE PRICE
A1: Current basic prices - PY - 2025
B2: Years | C2: ST | D2: PR | E2: ST+TK | F2: PR+TK | G2: PL1 | H2: Tkanivo placenty | I2: Tkanivo pupocnika | J2: Inflation rate 2025 | K2: FX rate
A3: SK | B3: 1 | C3: 80.663099 | D3: 92.567751 | E3: 102.21188 | F3: 114.11653 | G3: 197.02879 | H3: 0 | I3: 21.548782 | J3: 0.04 | K3: 1
B4: 10 | C4: 685.63067 | D4: 786.79748 | E4: 868.84643 | F4: 970.00188 | G4: 1674.7504 | H4: 0 | I4: 183.2044 | J4: 0.04 | K4: 1
B5: 20 | C5: 1209.9465 | D5: 1388.4595 | E5: 1533.2464 | F5: 1711.7707 | G5: 2955.4319 | H5: 0 | I5: 323.31124 | J5: 0.04 | K5: 1
A6: RO | B6: 1 | C6: 360 | D6: 490 | E6: 490 | F6: 620 | G6: 1050 | H6: 430 | I6: 130 | J6: 0.073 | K6: 5.0424
B7: 10 | C7: 3060 | D7: 4165 | E7: 4165 | F7: 5270 | G7: 8925 | H7: 3655 | I7: 1105 | J7: 0.073 | K7: 5.0424
B8: 20 | C8: 5400 | D8: 7350 | E8: 7350 | F8: 9300 | G8: 15750 | H8: 6450 | I8: 1950 | J8: 0.073 | K8: 5.0424
A9: HU | B9: 1 | C9: 30770 | D9: 39740 | E9: 38450 | F9: 47420 | G9: 0 | H9: 0 | I9: 7685 | J9: 0.044 | K9: 397.7675
B10: 10 | C10: 184620 | D10: 238440 | E10: 230700 | F10: 284520 | G10: 0 | H10: 0 | I10: 46100 | J10: 0.044 | K10: 397.7675
B11: 20 | C11: 307700 | D11: 397400 | E11: 384500 | F11: 474200 | G11: 0 | H11: 0 | I11: 76835 | J11: 0.044 | K11: 397.7675
A12: HU splatky | B12: 10 | I12: 11530 | J12: 0.044 | K12: 397.7675
B13: 20 | I13: 19215 | J13: 0.044 | K13: 397.7675
A14: CZ | B14: 1 | C14: 2182 | D14: 2730 | E14: 3605 | F14: 4152 | G14: 4932 | H14: 0 | I14: 0 | J14: 0.025 | K14: 24.6879
B15: 5 | C15: 9819 | D15: 12285 | E15: 16222.5 | F15: 18684 | G15: 22191 | H15: 0 | I15: 0 | J15: 0.025 | K15: 24.6879
B16: 10 | C16: 18547 | D16: 23205 | E16: 30642.5 | F16: 35292 | G16: 41915 | H16: 0 | I16: 0 | J16: 0.025 | K16: 24.6879
A17: AT | B17: 1 | C17: 65.446458 | D17: 76.539078 | E17: 87.631698 | F17: 98.724318 | G17: 0 | H17: 0 | I17: 76.539078 | J17: 0.036 | K17: 1 | L17: AT, IT: the annual rate of inflation is to be taken into account for an annual increase by more than 5%
B18: 5 | C18: 310.59336 | D18: 363.83794 | E18: 415.97325 | F18: 469.21783 | G18: 0 | H18: 0 | I18: 363.83794 | J18: 0.036 | K18: 1
B19: 10 | C19: 589.01812 | D19: 688.8517 | E19: 788.68528 | F19: 888.51886 | G19: 0 | H19: 0 | I19: 688.8517 | J19: 0.036 | K19: 1
A20: IT | B20: 1 | C20: 64.0542 | D20: 85.4056 | E20: 85.4056 | F20: 90.74345 | G20: 0 | H20: 0 | I20: 0 | J20: 0.015 | K20: 1 | L20: AT, IT: the annual rate of inflation is to be taken into account for an annual increase by more than 5%
B21: 10 | C21: 533.785 | D21: 629.8663 | E21: 715.2719 | F21: 747.299 | G21: 0 | H21: 0 | I21: 0 | J21: 0.015 | K21: 1
B22: 20 | C22: 960.813 | D22: 1067.57 | E22: 1174.327 | F22: 1281.084 | G22: 0 | H22: 0 | I22: 0 | J22: 0.015 | K22: 1
A25: Prices after inflation rate impact - local CCY - 2026
B26: Years | C26: ST | D26: PR | E26: ST+TK | F26: PR+TK | G26: PL1 | H26: Tkanivo placenty | I26: Tkanivo pupocnika
A27: SK | B27: 1 | C27: =+C3*(1+$J3) -> 83.889623 | D27: =+D3*(1+$J3) -> 96.270461 | E27: =+E3*(1+$J3) -> 106.30036 | F27: =+F3*(1+$J3) -> 118.68119 | G27: =+G3*(1+$J3) -> 204.90994 | H27: =+H3*(1+$J3) -> 0 | I27: =+I3*(1+$J3) -> 22.410733
B28: 10 | C28: =+C4*(1+$J4) -> 713.05589 | D28: =+D4*(1+$J4) -> 818.26938 | E28: =+E4*(1+$J4) -> 903.60028 | F28: =+F4*(1+$J4) -> 1008.802 | G28: =+G4*(1+$J4) -> 1741.7404 | H28: =+H4*(1+$J4) -> 0 | I28: =+I4*(1+$J4) -> 190.53258
B29: 20 | C29: =+C5*(1+$J5) -> 1258.3444 | D29: =+D5*(1+$J5) -> 1443.9978 | E29: =+E5*(1+$J5) -> 1594.5762 | F29: =+F5*(1+$J5) -> 1780.2415 | G29: =+G5*(1+$J5) -> 3073.6492 | H29: =+H5*(1+$J5) -> 0 | I29: =+I5*(1+$J5) -> 336.24369
A30: RO | B30: 1 | C30: =+C6*(1+$J6) -> 386.28 | D30: =+D6*(1+$J6) -> 525.77 | E30: =+E6*(1+$J6) -> 525.77 | F30: =+F6*(1+$J6) -> 665.26 | G30: =+G6*(1+$J6) -> 1126.65 | H30: =+H6*(1+$J6) -> 461.39 | I30: =+I6*(1+$J6) -> 139.49
B31: 10 | C31: =+C7*(1+$J7) -> 3283.38 | D31: =+D7*(1+$J7) -> 4469.045 | E31: =+E7*(1+$J7) -> 4469.045 | F31: =+F7*(1+$J7) -> 5654.71 | G31: =+G7*(1+$J7) -> 9576.525 | H31: =+H7*(1+$J7) -> 3921.815 | I31: =+I7*(1+$J7) -> 1185.665
B32: 20 | C32: =+C8*(1+$J8) -> 5794.2 | D32: =+D8*(1+$J8) -> 7886.55 | E32: =+E8*(1+$J8) -> 7886.55 | F32: =+F8*(1+$J8) -> 9978.9 | G32: =+G8*(1+$J8) -> 16899.75 | H32: =+H8*(1+$J8) -> 6920.85 | I32: =+I8*(1+$J8) -> 2092.35
A33: HU | B33: 1 | C33: =+C9*(1+$J9) -> 32123.88 | D33: =+D9*(1+$J9) -> 41488.56 | E33: =+E9*(1+$J9) -> 40141.8 | F33: =+F9*(1+$J9) -> 49506.48 | G33: =+G9*(1+$J9) -> 0 | H33: =+H9*(1+$J9) -> 0 | I33: =+I9*(1+$J9) -> 8023.14
B34: 10 | C34: =+C10*(1+$J10) -> 192743.28 | D34: =+D10*(1+$J10) -> 248931.36 | E34: =+E10*(1+$J10) -> 240850.8 | F34: =+F10*(1+$J10) -> 297038.88 | G34: =+G10*(1+$J10) -> 0 | H34: =+H10*(1+$J10) -> 0 | I34: =+I10*(1+$J10) -> 48128.4
B35: 20 | C35: =+C11*(1+$J11) -> 321238.8 | D35: =+D11*(1+$J11) -> 414885.6 | E35: =+E11*(1+$J11) -> 401418 | F35: =+F11*(1+$J11) -> 495064.8 | G35: =+G11*(1+$J11) -> 0 | H35: =+H11*(1+$J11) -> 0 | I35: =+I11*(1+$J11) -> 80215.74
A36: HU splatky | B36: 10 | I36: =+I12*(1+$J12) -> 12037.32
B37: 20 | I37: =+I13*(1+$J13) -> 20060.46
A38: CZ | B38: 1 | C38: =+C14*(1+$J14) -> 2236.55 | D38: =+D14*(1+$J14) -> 2798.25 | E38: =+E14*(1+$J14) -> 3695.125 | F38: =+F14*(1+$J14) -> 4255.8 | G38: =+G14*(1+$J14) -> 5055.3 | H38: 0 | I38: =+I14*(1+$J14) -> 0
B39: 5 | C39: =+C15*(1+$J15) -> 10064.475 | D39: =+D15*(1+$J15) -> 12592.125 | E39: =+E15*(1+$J15) -> 16628.062 | F39: =+F15*(1+$J15) -> 19151.1 | G39: =+G15*(1+$J15) -> 22745.775 | H39: 0 | I39: =+I15*(1+$J15) -> 0
B40: 10 | C40: =+C16*(1+$J16) -> 19010.675 | D40: =+D16*(1+$J16) -> 23785.125 | E40: =+E16*(1+$J16) -> 31408.562 | F40: =+F16*(1+$J16) -> 36174.3 | G40: =+G16*(1+$J16) -> 42962.875 | H40: 0 | I40: =+I16*(1+$J16) -> 0
A41: AT | B41: 1 | C41: =+C17*(1+$J17) -> 67.80253 | D41: =+D17*(1+$J17) -> 79.294485 | E41: =+E17*(1+$J17) -> 90.786439 | F41: =+F17*(1+$J17) -> 102.27839 | G41: =+G17*(1+$J17) -> 0 | H41: =+H17*(1+$J17) -> 0 | I41: =+I17*(1+$J17) -> 79.294485
B42: 5 | C42: =+C18*(1+$J18) -> 321.77472 | D42: =+D18*(1+$J18) -> 376.9361 | E42: =+E18*(1+$J18) -> 430.94829 | F42: =+F18*(1+$J18) -> 486.10967 | G42: =+G18*(1+$J18) -> 0 | H42: =+H18*(1+$J18) -> 0 | I42: =+I18*(1+$J18) -> 376.9361
...

Sheet SK
A1: SLOVAKIA
A3: PRICE LIST (from 1.1.2025) | B3: Classic | C3: Premium | D3: Cl.+Tissue | E3: PR.+Tissue | F3: Placenta | J3: CB* | K3: pupocnikova krv
B4: =+'COLLECTION PRICE'!C25 -> 1400 | C4: =+'COLLECTION PRICE'!D25 -> 1600 | D4: =+'COLLECTION PRICE'!E25 -> 1800 | E4: =+'COLLECTION PRICE'!F25 -> 2100 | F4: =+'COLLECTION PRICE'!G25 -> 2500 | G4: Collection | J4: PB* | K4: placentarna krv
B5: =+'STORAGE PRICE'!C74 -> 83.889623 | C5: =+'STORAGE PRICE'!D74 -> 96.270461 | D5: =+'STORAGE PRICE'!E74 -> 106.30036 | E5: =+'STORAGE PRICE'!F74 -> 118.68119 | F5: =+'STORAGE PRICE'!G74 -> 204.90994 | G5: 1 Year storage | J5: T (CB) | K5: tkanivo pupocnika
B6: =+'STORAGE PRICE'!C75 -> 713.05589 | C6: =+'STORAGE PRICE'!D75 -> 818.26938 | D6: =+'STORAGE PRICE'!E75 -> 903.60028 | E6: =+'STORAGE PRICE'!F75 -> 1008.802 | F6: =+'STORAGE PRICE'!G75 -> 1741.7404 | G6: 10 Years storage | J6: T (PB) | K6: tkanivo pupocnika
B7: =+'STORAGE PRICE'!C76 -> 1258.3444 | C7: =+'STORAGE PRICE'!D76 -> 1443.9978 | D7: =+'STORAGE PRICE'!E76 -> 1594.5762 | E7: =+'STORAGE PRICE'!F76 -> 1780.2415 | F7: =+'STORAGE PRICE'!G76 -> 3073.6492 | G7: 20 Years storage | J7: PL | K7: tkanivo placenty
A9: Failed Collection or Contamination
A10: Product | B10: CB* | C10: PB* | D10: T (CB) | E10: T (PB) | F10: PL | H10: Discounted
A11: Price - collection | B11: =+B4-H13 -> 900 | C11: =+C4-B4 -> 200 | D11: =+D4-B4 -> 400 | E11: =+E4-C4 -> 500 | F11: =+F4-E4 -> 400 | G11: Product | H11: price | J11: 15% discount | K11: 25% discount
A12: Price - storage | B12: =+B5 -> 83.889623 | C12: =+C5-B5 -> 12.380837 | D12: =+D5-B12 -> 22.410733 | E12: =+E5-C5 -> 22.410733 | F12: =+F5-E5 -> 86.228751 | G12: adjustment | H12: COLLECTION | I12: 1 YEAR STORAGE | J12: 10 YEAR STORAGE | K12: 20 YEAR STORAGE
A13: FLAAT FEE | B13: FALSE | C13: FALSE | D13: FALSE | E13: FALSE | F13: FALSE | G13: ALL | H13: 500 | L13: Cena za samostatne tkanivo popocnika kym nedojde k zmenev zmluve
A14: Classic | B14: TRUE | C14: FALSE | D14: FALSE | E14: FALSE | F14: FALSE | G14: Classic | H14: =+B4 -> 1400 | I14: =+B5 -> 83.889623 | J14: =+B6 -> 713.05589 | K14: =+B7 -> 1258.3444
A15: Premium | B15: TRUE | C15: TRUE | D15: FALSE | E15: FALSE | F15: FALSE | G15: Premium | H15: =+C4 -> 1600 | I15: =+C5 -> 96.270461 | J15: =+C6 -> 818.26938 | K15: =+C7 -> 1443.9978
A16: Premium | B16: TRUE | C16: FALSE | D16: FALSE | E16: FALSE | F16: FALSE | G16: CB | H16: =+$B$11+H13 -> 1400 | I16: =+$B$12 -> 83.889623 | J16: =+I16*10*(100%-15%) -> 713.0618 | K16: =+I16*20*(100%-25%) -> 1258.3444
A17: Premium | B17: FALSE | C17: TRUE | D17: FALSE | E17: FALSE | F17: FALSE | G17: PB | H17: =+$C$11+H13 -> 700 | I17: =+$C$12 -> 12.380837 | J17: =+I17*10*(100%-15%) -> 105.23712 | K17: =+I17*20*(100%-25%) -> 185.71256
A18: Classic+Tissue | B18: TRUE | C18: FALSE | D18: TRUE | E18: FALSE | F18: FALSE | G18: Classic+Tissue | H18: =+D4 -> 1800 | I18: =+D5 -> 106.30036 | J18: =+D6 -> 903.60028 | K18: =+D7 -> 1594.5762
A19: Classic+Tissue | B19: TRUE | C19: FALSE | D19: FALSE | E19: FALSE | F19: FALSE | G19: CB | H19: =+$B$11+H13 -> 1400 | I19: =+$B$12 -> 83.889623 | J19: =+I19*10*(100%-15%) -> 713.0618 | K19: =+I19*20*(100%-25%) -> 1258.3444
A20: Classic+Tissue | B20: FALSE | C20: FALSE | D20: TRUE | E20: FALSE | F20: FALSE | G20: T (CB) | H20: =+$D$11+H13 -> 900 | I20: =+$D$12 -> 22.410733 | J20: =+I20*10*(100%-15%) -> 190.49123 | K20: =+I20*20*(100%-25%) -> 336.161 | L20: v zmluve je aktualne uvedena cena za odber samostatneho tkaniva 1200 EUR
A21: Premium+Tissue | B21: TRUE | C21: TRUE | D21: FALSE | E21: TRUE | F21: FALSE | G21: Premium+Tissue | H21: =+E4 -> 2100 | I21: =+E5 -> 118.68119 | J21: =+E6 -> 1008.802 | K21: =+E7 -> 1780.2415
A22: Premium+Tissue | B22: TRUE | C22: FALSE | D22: FALSE | E22: FALSE | F22: FALSE | G22: CB | H22: =+$B$11+H13 -> 1400 | I22: =+$B$12 -> 83.889623 | J22: =+I22*10*(100%-15%) -> 713.0618 | K22: =+I22*20*(100%-25%) -> 1258.3444
A23: Premium+Tissue | B23: TRUE | C23: TRUE | D23: FALSE | E23: FALSE | F23: FALSE | G23: CB + PB | H23: =+$B$11+$C$11+H13 -> 1600 | I23: =+$B$12+$C$12 -> 96.270461 | J23: =+I23*10*(100%-15%) -> 818.29892 | K23: =+I23*20*(100%-25%) -> 1444.0569
A24: Premium+Tissue | B24: TRUE | C24: FALSE | D24: TRUE | E24: FALSE | F24: FALSE | G24: CB + T (CB) | H24: =+$B$11+$D$11+H13 -> 1800 | I24: =+$B$12+$D$12 -> 106.30036 | J24: =+I24*10*(100%-15%) -> 903.55303 | K24: =+I24*20*(100%-25%) -> 1594.5053
A25: Premium+Tissue | B25: FALSE | C25: TRUE | D25: FALSE | E25: FALSE | F25: FALSE | G25: PB | H25: =+$C$11+H13 -> 700 | I25: =+$C$12 -> 12.380837 | J25: =+I25*10*(100%-15%) -> 105.23712 | K25: =+I25*20*(100%-25%) -> 185.71256
A26: Premium+Tissue | B26: FALSE | C26: TRUE | D26: FALSE | E26: TRUE | F26: FALSE | G26: PB+T (PB) | H26: =+$C$11+$E$11+H13 -> 1200 | I26: =+$C$12+$E$12 -> 34.79157 | J26: =+I26*10*(100%-15%) -> 295.72835 | K26: =+I26*20*(100%-25%) -> 521.87355
A27: Premium+Tissue | B27: FALSE | C27: FALSE | D27: FALSE | E27: TRUE | F27: FALSE | G27: T (PB) | H27: =+$E$11+H13 -> 1000 | I27: =+$E$12 -> 22.410733 | J27: =+I27*10*(100%-15%) -> 190.49123 | K27: =+I27*20*(100%-25%) -> 336.161 | L27: v zmluve je aktualne uvedena cena za odber samostatneho tkaniva 1200 EUR
A28: PLACENTA | B28: TRUE | C28: TRUE | D28: FALSE | E28: TRUE | F28: TRUE | G28: Placenta | H28: =+F4 -> 2500 | I28: =+F5 -> 204.90994 | J28: =+F6 -> 1741.7404 | K28: =+F7 -> 3073.6492
A29: PLACENTA | B29: TRUE | C29: FALSE | D29: FALSE | E29: FALSE | F29: FALSE | G29: CB | H29: =+$B$11+H13 -> 1400 | I29: =+$B$12 -> 83.889623 | J29: =+I29*10*(100%-15%) -> 713.0618 | K29: =+I29*20*(100%-25%) -> 1258.3444
A30: PLACENTA | B30: TRUE | C30: TRUE | D30: FALSE | E30: FALSE | F30: FALSE | G30: CB + PB | H30: =+$B$11+$C$11+H13 -> 1600 | I30: =+$B$12+$C$12 -> 96.270461 | J30: =+I30*10*(100%-15%) -> 818.29892 | K30: =+I30*20*(100%-25%) -> 1444.0569
A31: PLACENTA | B31: TRUE | C31: TRUE | D31: FALSE | E31: TRUE | F31: FALSE | G31: CB + PB + T (PB) | H31: =+$B$11+$C$11+$E$11+H13 -> 2100 | I31: =+$B$12+$C$12+$E$12 -> 118.68119 | J31: =+I31*10*(100%-15%) -> 1008.7901 | K31: =+I31*20*(100%-25%) -> 1780.2179
A32: PLACENTA | B32: TRUE | C32: FALSE | D32: TRUE | E32: FALSE | F32: FALSE | G32: CB + T (CB) | H32: =+$B$11+$D$11+H13 -> 1800 | I32: =+$B$12+$D$12 -> 106.30036 | J32: =+I32*10*(100%-15%) -> 903.55303 | K32: =+I32*20*(100%-25%) -> 1594.5053
A33: PLACENTA | B33: FALSE | C33: TRUE | D33: FALSE | E33: FALSE | F33: FALSE | G33: PB | H33: =+$C$11+H13 -> 700 | I33: =+$C$12 -> 12.380837 | J33: =+I33*10*(100%-15%) -> 105.23712 | K33: =+I33*20*(100%-25%) -> 185.71256
A34: PLACENTA | B34: FALSE | C34: TRUE | D34: FALSE | E34: TRUE | F34: FALSE | G34: PB+T (PB) | H34: =+$C$11+$E$11+H13 -> 1200 | I34: =+$C$12+$E$12 -> 34.79157 | J34: =+I34*10*(100%-15%) -> 295.72835 | K34: =+I34*20*(100%-25%) -> 521.87355
A35: PLACENTA | B35: FALSE | C35: FALSE | D35: FALSE | E35: TRUE | F35: FALSE | G35: T (PB) | H35: =+$E$11+H13 -> 1000 | I35: =+$E$12 -> 22.410733 | J35: =+I35*10*(100%-15%) -> 190.49123 | K35: =+I35*20*(100%-25%) -> 336.161 | L35: v zmluve je aktualne uvedena cena za odber samostatneho tkaniva 1200 EUR
A36: PLACENTA | B36: FALSE | C36: FALSE | D36: FALSE | E36: FALSE | F36: TRUE | G36: PL | H36: =+$F$11+H13 -> 900 | I36: =+$F$12 -> 86.228751 | J36: =+I36*10*(100%-15%) -> 732.94438 | K36: =+I36*20*(100%-25%) -> 1293.4313
A37: PLACENTA | B37: TRUE | C37: FALSE | D37: FALSE | E37: FALSE | F37: TRUE | G37: CB+PL | H37: =+$B$11+$F$11+H13 -> 1800 | I37: =+$B$12+$F$12 -> 170.11837 | J37: =+I37*10*(100%-15%) -> 1446.0062 | K37: =+I37*20*(100%-25%) -> 2551.7756
A38: PLACENTA | B38: TRUE | C38: TRUE | D38: FALSE | E38: FALSE | F38: TRUE | G38: CB+PB+PL | H38: =+$B$11+$C$11+$F$11+H13 -> 2000 | I38: =+$B$12+$C$12+$F$12 -> 182.49921 | J38: =+I38*10*(100%-15%) -> 1551.2433 | K38: =+I38*20*(100%-25%) -> 2737.4882
A39: PLACENTA | B39: TRUE | C39: FALSE | D39: FALSE | E39: TRUE | F39: TRUE | G39: CB+T(PB)+PL | H39: =+$B$11+$E$11+$F$11+H13 -> 2300 | I39: =+$B$12+$E$12+$F$12 -> 192.52911 | J39: =+I39*10*(100%-15%) -> 1636.4974 | K39: =+I39*20*(100%-25%) -> 2887.9366
A40: PLACENTA | B40: FALSE | C40: TRUE | D40: FALSE | E40: FALSE | F40: TRUE | G40: PB+PL | H40: =+$C$11+$F$11+H13 -> 1100 | I40: =+$C$12+$F$12 -> 98.609588 | J40: =+I40*10*(100%-15%) -> 838.1815 | K40: =+I40*20*(100%-25%) -> 1479.1438
A41: PLACENTA | B41: FALSE | C41: TRUE | D41: FALSE | E41: TRUE | F41: TRUE | G41: PB+T(PB)+PL | H41: =+$C$11+$E$11+$F$11+H13 -> 1600 | I41: =+$C$12+$E$12+$F$12 -> 121.02032 | J41: =+I41*10*(100%-15%) -> 1028.6727 | K41: =+I41*20*(100%-25%) -> 1815.3048
A42: PLACENTA | B42: FALSE | C42: FALSE | D42: FALSE | E42: TRUE | F42: TRUE | G42: T(PB)+PL | H42: =+$E$11+$F$11+H13 -> 1400 | I42: =+$E$12+$F$12 -> 108.63948 | J42: =+I42*10*(100%-15%) -> 923.43561 | K42: =+I42*20*(100%-25%) -> 1629.5923
...

Sheet CZ
A1: CZECHIA
A3: PRICE LIST (from 1.1.2025) | B3: Classic | C3: Premium | D3: Cl.+Tissue | E3: PR.+Tissue | F3: Placenta | J3: CB* | K3: pupocnikova krv
B4: =+'COLLECTION PRICE'!C34 -> 35000 | C4: =+'COLLECTION PRICE'!D34 -> 40000 | D4: =+'COLLECTION PRICE'!E34 -> 45000 | E4: =+'COLLECTION PRICE'!F34 -> 52500 | F4: =+'COLLECTION PRICE'!G34 -> 62500 | G4: Collection | J4: PB | K4: placentarna krv
B5: =+'STORAGE PRICE'!C61 -> 2237 | C5: =+'STORAGE PRICE'!D61 -> 2799 | D5: =+'STORAGE PRICE'!E61 -> 3696 | E5: =+'STORAGE PRICE'!F61 -> 4256 | F5: =+'STORAGE PRICE'!G61 -> 5056 | G5: 1 Year storage | J5: T (CB) | K5: tkanivo pupocnika
B6: =+'STORAGE PRICE'!C62 -> 10066.5 | C6: =+'STORAGE PRICE'!D62 -> 12595.5 | D6: =+'STORAGE PRICE'!E62 -> 16632 | E6: =+'STORAGE PRICE'!F62 -> 19152 | F6: =+'STORAGE PRICE'!G62 -> 22746 | G6: 5 Years storage | J6: T (PB) | K6: tkanivo pupocnika
B7: =+'STORAGE PRICE'!C63 -> 19014.5 | C7: =+'STORAGE PRICE'!D63 -> 23791.5 | D7: =+'STORAGE PRICE'!E63 -> 31416 | E7: =+'STORAGE PRICE'!F63 -> 36176 | F7: =+'STORAGE PRICE'!G63 -> 42963 | G7: 10 Years storage | J7: PL | K7: tkanivo placenty
A9: Failed Collection or Contamination
A10: Product | B10: CB* | C10: PB | D10: T (CB) | E10: T (PB) | F10: PL | H10: Discounted
A11: Price - collection | B11: =+B4-H13 -> 22500 | C11: =+C4-B4 -> 5000 | D11: =+D4-B4 -> 10000 | E11: =+E4-C4 -> 12500 | F11: =+F4-E4 -> 10000 | G11: Product | H11: price | J11: 10% discount | K11: 15% discount | M11: Collection
A12: Price - storage | B12: =+B5 -> 2237 | C12: =+C5-B5 -> 562 | D12: =+D5-B12 -> 1459 | E12: =+E5-C5 -> 1457 | F12: =+F5-E5 -> 800 | G12: adjustment | H12: COLLECTION | I12: 1 YEAR STORAGE | J12: 5 YEAR STORAGE | K12: 10 YEAR STORAGE | M12: in EUR
A13: FLAAT FEE | B13: FALSE | C13: FALSE | D13: FALSE | E13: FALSE | F13: FALSE | G13: ALL | H13: =500*25 -> 12500 | M13: =+H13/25 -> 500
A14: Classic | B14: TRUE | C14: FALSE | D14: FALSE | E14: FALSE | F14: FALSE | G14: Classic | H14: =+B4 -> 35000 | I14: =+B5 -> 2237 | J14: =+B6 -> 10066.5 | K14: =+B7 -> 19014.5 | M14: =+H14/25 -> 1400
A15: Premium | B15: TRUE | C15: TRUE | D15: FALSE | E15: FALSE | F15: FALSE | G15: Premium | H15: =+C4 -> 40000 | I15: =+C5 -> 2799 | J15: =+C6 -> 12595.5 | K15: =+C7 -> 23791.5 | M15: =+H15/25 -> 1600
A16: Premium | B16: TRUE | C16: FALSE | D16: FALSE | E16: FALSE | F16: FALSE | G16: CB | H16: =+$B$11+H13 -> 35000 | I16: =+$B$12 -> 2237 | J16: =+I16*5*(100%-10%) -> 10066.5 | K16: =+I16*10*(100%-15%) -> 19014.5 | M16: =+H16/25 -> 1400
A17: Premium | B17: FALSE | C17: TRUE | D17: FALSE | E17: FALSE | F17: FALSE | G17: PB | H17: =+$C$11+H13 -> 17500 | I17: =+$C$12 -> 562 | J17: =+I17*5*(100%-10%) -> 2529 | K17: =+I17*10*(100%-15%) -> 4777 | M17: =+H17/25 -> 700
A18: Classic+Tissue | B18: TRUE | C18: FALSE | D18: TRUE | E18: FALSE | F18: FALSE | G18: Classic+Tissue | H18: =+D4 -> 45000 | I18: =+D5 -> 3696 | J18: =+D6 -> 16632 | K18: =+D7 -> 31416 | M18: =+H18/25 -> 1800
A19: Classic+Tissue | B19: TRUE | C19: FALSE | D19: FALSE | E19: FALSE | F19: FALSE | G19: CB | H19: =+$B$11+H13 -> 35000 | I19: =+$B$12 -> 2237 | J19: =+I19*5*(100%-10%) -> 10066.5 | K19: =+I19*10*(100%-15%) -> 19014.5 | M19: =+H19/25 -> 1400
A20: Classic+Tissue | B20: FALSE | C20: FALSE | D20: TRUE | E20: FALSE | F20: FALSE | G20: T (CB) | H20: =+$D$11+H13 -> 22500 | I20: =+$D$12 -> 1459 | J20: =+I20*5*(100%-10%) -> 6565.5 | K20: =+I20*10*(100%-15%) -> 12401.5 | M20: =+H20/25 -> 900
A21: Premium+Tissue | B21: TRUE | C21: TRUE | D21: FALSE | E21: TRUE | F21: FALSE | G21: Premium+Tissue | H21: =+E4 -> 52500 | I21: =+E5 -> 4256 | J21: =+E6 -> 19152 | K21: =+E7 -> 36176 | M21: =+H21/25 -> 2100
A22: Premium+Tissue | B22: TRUE | C22: FALSE | D22: FALSE | E22: FALSE | F22: FALSE | G22: CB | H22: =+$B$11+H13 -> 35000 | I22: =+$B$12 -> 2237 | J22: =+I22*5*(100%-10%) -> 10066.5 | K22: =+I22*10*(100%-15%) -> 19014.5 | M22: =+H22/25 -> 1400
A23: Premium+Tissue | B23: TRUE | C23: TRUE | D23: FALSE | E23: FALSE | F23: FALSE | G23: CB + PB | H23: =+$B$11+$C$11+H13 -> 40000 | I23: =+$B$12+$C$12 -> 2799 | J23: =+I23*5*(100%-10%) -> 12595.5 | K23: =+I23*10*(100%-15%) -> 23791.5 | M23: =+H23/25 -> 1600
A24: Premium+Tissue | B24: TRUE | C24: FALSE | D24: TRUE | E24: FALSE | F24: FALSE | G24: CB + T (CB) | H24: =+$B$11+$D$11+H13 -> 45000 | I24: =+$B$12+$D$12 -> 3696 | J24: =+I24*5*(100%-10%) -> 16632 | K24: =+I24*10*(100%-15%) -> 31416 | M24: =+H24/25 -> 1800
A25: Premium+Tissue | B25: FALSE | C25: TRUE | D25: FALSE | E25: FALSE | F25: FALSE | G25: PB | H25: =+$C$11+H13 -> 17500 | I25: =+$C$12 -> 562 | J25: =+I25*5*(100%-10%) -> 2529 | K25: =+I25*10*(100%-15%) -> 4777 | M25: =+H25/25 -> 700
A26: Premium+Tissue | B26: FALSE | C26: TRUE | D26: FALSE | E26: TRUE | F26: FALSE | G26: PB+T (PB) | H26: =+$C$11+$E$11+H13 -> 30000 | I26: =+$C$12+$E$12 -> 2019 | J26: =+I26*5*(100%-10%) -> 9085.5 | K26: =+I26*10*(100%-15%) -> 17161.5 | M26: =+H26/25 -> 1200
A27: Premium+Tissue | B27: FALSE | C27: FALSE | D27: FALSE | E27: TRUE | F27: FALSE | G27: T (PB) | H27: =+$E$11+H13 -> 25000 | I27: =+$E$12 -> 1457 | J27: =+I27*5*(100%-10%) -> 6556.5 | K27: =+I27*10*(100%-15%) -> 12384.5 | M27: =+H27/25 -> 1000
A28: PLACENTA | B28: TRUE | C28: TRUE | D28: FALSE | E28: TRUE | F28: TRUE | G28: Placenta | H28: =+F4 -> 62500 | I28: =+F5 -> 5056 | J28: =+F6 -> 22746 | K28: =+F7 -> 42963 | M28: =+H28/25 -> 2500
A29: PLACENTA | B29: TRUE | C29: FALSE | D29: FALSE | E29: FALSE | F29: FALSE | G29: CB | H29: =+$B$11+H13 -> 35000 | I29: =+$B$12 -> 2237 | J29: =+I29*5*(100%-10%) -> 10066.5 | K29: =+I29*10*(100%-15%) -> 19014.5 | M29: =+H29/25 -> 1400
A30: PLACENTA | B30: TRUE | C30: TRUE | D30: FALSE | E30: FALSE | F30: FALSE | G30: CB + PB | H30: =+$B$11+$C$11+H13 -> 40000 | I30: =+$B$12+$C$12 -> 2799 | J30: =+I30*5*(100%-10%) -> 12595.5 | K30: =+I30*10*(100%-15%) -> 23791.5 | M30: =+H30/25 -> 1600
A31: PLACENTA | B31: TRUE | C31: TRUE | D31: FALSE | E31: TRUE | F31: FALSE | G31: CB + PB + T (PB) | H31: =+$B$11+$C$11+$E$11+H13 -> 52500 | I31: =+$B$12+$C$12+$E$12 -> 4256 | J31: =+I31*5*(100%-10%) -> 19152 | K31: =+I31*10*(100%-15%) -> 36176 | M31: =+H31/25 -> 2100
A32: PLACENTA | B32: TRUE | C32: FALSE | D32: TRUE | E32: FALSE | F32: FALSE | G32: CB + T (CB) | H32: =+$B$11+$D$11+H13 -> 45000 | I32: =+$B$12+$D$12 -> 3696 | J32: =+I32*5*(100%-10%) -> 16632 | K32: =+I32*10*(100%-15%) -> 31416 | M32: =+H32/25 -> 1800
A33: PLACENTA | B33: FALSE | C33: TRUE | D33: FALSE | E33: FALSE | F33: FALSE | G33: PB | H33: =+$C$11+H13 -> 17500 | I33: =+$C$12 -> 562 | J33: =+I33*5*(100%-10%) -> 2529 | K33: =+I33*10*(100%-15%) -> 4777 | M33: =+H33/25 -> 700
A34: PLACENTA | B34: FALSE | C34: TRUE | D34: FALSE | E34: TRUE | F34: FALSE | G34: PB+T (PB) | H34: =+$C$11+$E$11+H13 -> 30000 | I34: =+$C$12+$E$12 -> 2019 | J34: =+I34*5*(100%-10%) -> 9085.5 | K34: =+I34*10*(100%-15%) -> 17161.5 | M34: =+H34/25 -> 1200
A35: PLACENTA | B35: FALSE | C35: FALSE | D35: FALSE | E35: TRUE | F35: FALSE | G35: T (PB) | H35: =+$E$11+H13 -> 25000 | I35: =+$E$12 -> 1457 | J35: =+I35*5*(100%-10%) -> 6556.5 | K35: =+I35*10*(100%-15%) -> 12384.5 | M35: =+H35/25 -> 1000
A36: PLACENTA | B36: FALSE | C36: FALSE | D36: FALSE | E36: FALSE | F36: TRUE | G36: PL | H36: =+$F$11+H13 -> 22500 | I36: =+$F$12 -> 800 | J36: =+I36*5*(100%-10%) -> 3600 | K36: =+I36*10*(100%-15%) -> 6800 | M36: =+H36/25 -> 900
A37: PLACENTA | B37: TRUE | C37: FALSE | D37: FALSE | E37: FALSE | F37: TRUE | G37: CB+PL | H37: =+$B$11+$F$11+H13 -> 45000 | I37: =+$B$12+$F$12 -> 3037 | J37: =+I37*5*(100%-10%) -> 13666.5 | K37: =+I37*10*(100%-15%) -> 25814.5 | M37: =+H37/25 -> 1800
A38: PLACENTA | B38: TRUE | C38: TRUE | D38: FALSE | E38: FALSE | F38: TRUE | G38: CB+PB+PL | H38: =+$B$11+$C$11+$F$11+H13 -> 50000 | I38: =+$B$12+$C$12+$F$12 -> 3599 | J38: =+I38*5*(100%-10%) -> 16195.5 | K38: =+I38*10*(100%-15%) -> 30591.5 | M38: =+H38/25 -> 2000
A39: PLACENTA | B39: TRUE | C39: FALSE | D39: FALSE | E39: TRUE | F39: TRUE | G39: CB+T(PB)+PL | H39: =+$B$11+$E$11+$F$11+H13 -> 57500 | I39: =+$B$12+$E$12+$F$12 -> 4494 | J39: =+I39*5*(100%-10%) -> 20223 | K39: =+I39*10*(100%-15%) -> 38199 | M39: =+H39/25 -> 2300
A40: PLACENTA | B40: FALSE | C40: TRUE | D40: FALSE | E40: FALSE | F40: TRUE | G40: PB+PL | H40: =+$C$11+$F$11+H13 -> 27500 | I40: =+$C$12+$F$12 -> 1362 | J40: =+I40*5*(100%-10%) -> 6129 | K40: =+I40*10*(100%-15%) -> 11577 | M40: =+H40/25 -> 1100
A41: PLACENTA | B41: FALSE | C41: TRUE | D41: FALSE | E41: TRUE | F41: TRUE | G41: PB+T(PB)+PL | H41: =+$C$11+$E$11+$F$11+H13 -> 40000 | I41: =+$C$12+$E$12+$F$12 -> 2819 | J41: =+I41*5*(100%-10%) -> 12685.5 | K41: =+I41*10*(100%-15%) -> 23961.5 | M41: =+H41/25 -> 1600
A42: PLACENTA | B42: FALSE | C42: FALSE | D42: FALSE | E42: TRUE | F42: TRUE | G42: T(PB)+PL | H42: =+$E$11+$F$11+H13 -> 35000 | I42: =+$E$12+$F$12 -> 2257 | J42: =+I42*5*(100%-10%) -> 10156.5 | K42: =+I42*10*(100%-15%) -> 19184.5 | M42: =+H42/25 -> 1400
...

Sheet RO
A1: ROMANIA
A3: PRICE LIST (from 1.1.2025) | B3: Classic | C3: Premium | D3: Cl.+Tissue | E3: PR.+Tissue | F3: Placenta | J3: CB* | K3: cord blood
B4: =+'COLLECTION PRICE'!C28 -> 7000 | C4: =+'COLLECTION PRICE'!D28 -> 8000 | D4: =+'COLLECTION PRICE'!E28 -> 9000 | E4: =+'COLLECTION PRICE'!F28 -> 10500 | F4: =+'COLLECTION PRICE'!G28 -> 12500 | G4: Collection | J4: PB | K4: placental blood
B5: =+'STORAGE PRICE'!C53 -> 390 | C5: =+'STORAGE PRICE'!D53 -> 530 | D5: =+'STORAGE PRICE'!E53 -> 530 | E5: =+'STORAGE PRICE'!F53 -> 670 | F5: =+'STORAGE PRICE'!G53 -> 1130 | G5: 1 Year storage | J5: T (CB) | K5: cord tissue
B6: =+'STORAGE PRICE'!C54 -> 3315 | C6: =+'STORAGE PRICE'!D54 -> 4505 | D6: =+'STORAGE PRICE'!E54 -> 4505 | E6: =+'STORAGE PRICE'!F54 -> 5695 | F6: =+'STORAGE PRICE'!G54 -> 9605 | G6: 10 Years storage | J6: T (PB) | K6: cord tissue
B7: =+'STORAGE PRICE'!C55 -> 5850 | C7: =+'STORAGE PRICE'!D55 -> 7950 | D7: =+'STORAGE PRICE'!E55 -> 7950 | E7: =+'STORAGE PRICE'!F55 -> 10050 | F7: =+'STORAGE PRICE'!G55 -> 16950 | G7: 20 Years storage | J7: PL | K7: placenta
A9: Failed Collection or Contamination
A10: Product | B10: CB* | C10: PB | D10: T (CB) | E10: T (PB) | F10: PL | H10: Discounted
A11: Price - collection | B11: =+B4-H13 -> 4500 | C11: =+C4-B4 -> 1000 | D11: =+D4-B4 -> 2000 | E11: =+E4-C4 -> 2500 | F11: =+F4-E4 -> 2000 | G11: Product | H11: price | J11: 15% discount | K11: 25% discount | M11: Collection
A12: Price - storage | B12: =+B5 -> 390 | C12: =+C5-B5 -> 140 | D12: =+D5-B12 -> 140 | E12: =+E5-C5 -> 140 | F12: =+F5-E5 -> 460 | G12: adjustment | H12: COLLECTION | I12: 1 YEAR STORAGE | J12: 10 YEAR STORAGE | K12: 20 YEAR STORAGE | M12: in EUR
A13: FLAAT FEE | B13: FALSE | C13: FALSE | D13: FALSE | E13: FALSE | F13: FALSE | G13: ALL | H13: 2500 | L13: Price for Tissue and Placenta ONLY till contract will be changed | M13: =+H13/5 -> 500
A14: Classic | B14: TRUE | C14: FALSE | D14: FALSE | E14: FALSE | F14: FALSE | G14: Classic | H14: =+B4 -> 7000 | I14: =+B5 -> 390 | J14: =+B6 -> 3315 | K14: =+B7 -> 5850 | M14: =+H14/5 -> 1400
A15: Premium | B15: TRUE | C15: TRUE | D15: FALSE | E15: FALSE | F15: FALSE | G15: Premium | H15: =+C4 -> 8000 | I15: =+C5 -> 530 | J15: =+C6 -> 4505 | K15: =+C7 -> 7950 | M15: =+H15/5 -> 1600
A16: Premium | B16: TRUE | C16: FALSE | D16: FALSE | E16: FALSE | F16: FALSE | G16: CB | H16: =+$B$11+H13 -> 7000 | I16: =+$B$12 -> 390 | J16: =+I16*10*(100%-15%) -> 3315 | K16: =+I16*20*(100%-25%) -> 5850 | M16: =+H16/5 -> 1400
A17: Premium | B17: FALSE | C17: TRUE | D17: FALSE | E17: FALSE | F17: FALSE | G17: PB | H17: =+$C$11+H13 -> 3500 | I17: =+$C$12 -> 140 | J17: =+I17*10*(100%-15%) -> 1190 | K17: =+I17*20*(100%-25%) -> 2100 | M17: =+H17/5 -> 700
A18: Classic+Tissue | B18: TRUE | C18: FALSE | D18: TRUE | E18: FALSE | F18: FALSE | G18: Classic+Tissue | H18: =+D4 -> 9000 | I18: =+D5 -> 530 | J18: =+D6 -> 4505 | K18: =+D7 -> 7950 | M18: =+H18/5 -> 1800
A19: Classic+Tissue | B19: TRUE | C19: FALSE | D19: FALSE | E19: FALSE | F19: FALSE | G19: CB | H19: =+$B$11+H13 -> 7000 | I19: =+$B$12 -> 390 | J19: =+I19*10*(100%-15%) -> 3315 | K19: =+I19*20*(100%-25%) -> 5850 | M19: =+H19/5 -> 1400
A20: Classic+Tissue | B20: FALSE | C20: FALSE | D20: TRUE | E20: FALSE | F20: FALSE | G20: T (CB) | H20: =+$D$11+H13 -> 4500 | I20: =+$D$12 -> 140 | J20: =+I20*10*(100%-15%) -> 1190 | K20: =+I20*20*(100%-25%) -> 2100 | L20: price for collection is written in contract in value 3 000 RON | M20: =+H20/5 -> 900
A21: Premium+Tissue | B21: TRUE | C21: TRUE | D21: FALSE | E21: TRUE | F21: FALSE | G21: Premium+Tissue | H21: =+E4 -> 10500 | I21: =+E5 -> 670 | J21: =+E6 -> 5695 | K21: =+E7 -> 10050 | M21: =+H21/5 -> 2100
A22: Premium+Tissue | B22: TRUE | C22: FALSE | D22: FALSE | E22: FALSE | F22: FALSE | G22: CB | H22: =+$B$11+H13 -> 7000 | I22: =+$B$12 -> 390 | J22: =+I22*10*(100%-15%) -> 3315 | K22: =+I22*20*(100%-25%) -> 5850 | M22: =+H22/5 -> 1400
A23: Premium+Tissue | B23: TRUE | C23: TRUE | D23: FALSE | E23: FALSE | F23: FALSE | G23: CB + PB | H23: =+$B$11+$C$11+H13 -> 8000 | I23: =+$B$12+$C$12 -> 530 | J23: =+I23*10*(100%-15%) -> 4505 | K23: =+I23*20*(100%-25%) -> 7950 | M23: =+H23/5 -> 1600
A24: Premium+Tissue | B24: TRUE | C24: FALSE | D24: TRUE | E24: FALSE | F24: FALSE | G24: CB + T (CB) | H24: =+$B$11+$D$11+H13 -> 9000 | I24: =+$B$12+$D$12 -> 530 | J24: =+I24*10*(100%-15%) -> 4505 | K24: =+I24*20*(100%-25%) -> 7950 | M24: =+H24/5 -> 1800
A25: Premium+Tissue | B25: FALSE | C25: TRUE | D25: FALSE | E25: FALSE | F25: FALSE | G25: PB | H25: =+$C$11+H13 -> 3500 | I25: =+$C$12 -> 140 | J25: =+I25*10*(100%-15%) -> 1190 | K25: =+I25*20*(100%-25%) -> 2100 | M25: =+H25/5 -> 700
A26: Premium+Tissue | B26: FALSE | C26: TRUE | D26: FALSE | E26: TRUE | F26: FALSE | G26: PB+T (PB) | H26: =+$C$11+$E$11+H13 -> 6000 | I26: =+$C$12+$E$12 -> 280 | J26: =+I26*10*(100%-15%) -> 2380 | K26: =+I26*20*(100%-25%) -> 4200 | M26: =+H26/5 -> 1200
A27: Premium+Tissue | B27: FALSE | C27: FALSE | D27: FALSE | E27: TRUE | F27: FALSE | G27: T (PB) | H27: =+$E$11+H13 -> 5000 | I27: =+$E$12 -> 140 | J27: =+I27*10*(100%-15%) -> 1190 | K27: =+I27*20*(100%-25%) -> 2100 | L27: price for collection is written in contract in value 3 000 RON | M27: =+H27/5 -> 1000
A28: PLACENTA | B28: TRUE | C28: TRUE | D28: FALSE | E28: TRUE | F28: TRUE | G28: Placenta | H28: =+F4 -> 12500 | I28: =+F5 -> 1130 | J28: =+F6 -> 9605 | K28: =+F7 -> 16950 | M28: =+H28/5 -> 2500
A29: PLACENTA | B29: TRUE | C29: FALSE | D29: FALSE | E29: FALSE | F29: FALSE | G29: CB | H29: =+$B$11+H13 -> 7000 | I29: =+$B$12 -> 390 | J29: =+I29*10*(100%-15%) -> 3315 | K29: =+I29*20*(100%-25%) -> 5850 | M29: =+H29/5 -> 1400
A30: PLACENTA | B30: TRUE | C30: TRUE | D30: FALSE | E30: FALSE | F30: FALSE | G30: CB + PB | H30: =+$B$11+$C$11+H13 -> 8000 | I30: =+$B$12+$C$12 -> 530 | J30: =+I30*10*(100%-15%) -> 4505 | K30: =+I30*20*(100%-25%) -> 7950 | M30: =+H30/5 -> 1600
A31: PLACENTA | B31: TRUE | C31: TRUE | D31: FALSE | E31: TRUE | F31: FALSE | G31: CB + PB + T (PB) | H31: =+$B$11+$C$11+$E$11+H13 -> 10500 | I31: =+$B$12+$C$12+$E$12 -> 670 | J31: =+I31*10*(100%-15%) -> 5695 | K31: =+I31*20*(100%-25%) -> 10050 | M31: =+H31/5 -> 2100
A32: PLACENTA | B32: TRUE | C32: FALSE | D32: TRUE | E32: FALSE | F32: FALSE | G32: CB + T (CB) | H32: =+$B$11+$D$11+H13 -> 9000 | I32: =+$B$12+$D$12 -> 530 | J32: =+I32*10*(100%-15%) -> 4505 | K32: =+I32*20*(100%-25%) -> 7950 | M32: =+H32/5 -> 1800
A33: PLACENTA | B33: FALSE | C33: TRUE | D33: FALSE | E33: FALSE | F33: FALSE | G33: PB | H33: =+$C$11+H13 -> 3500 | I33: =+$C$12 -> 140 | J33: =+I33*10*(100%-15%) -> 1190 | K33: =+I33*20*(100%-25%) -> 2100 | M33: =+H33/5 -> 700
A34: PLACENTA | B34: FALSE | C34: TRUE | D34: FALSE | E34: TRUE | F34: FALSE | G34: PB+T (PB) | H34: =+$C$11+$E$11+H13 -> 6000 | I34: =+$C$12+$E$12 -> 280 | J34: =+I34*10*(100%-15%) -> 2380 | K34: =+I34*20*(100%-25%) -> 4200 | M34: =+H34/5 -> 1200
A35: PLACENTA | B35: FALSE | C35: FALSE | D35: FALSE | E35: TRUE | F35: FALSE | G35: T (PB) | H35: =+$E$11+H13 -> 5000 | I35: =+$E$12 -> 140 | J35: =+I35*10*(100%-15%) -> 1190 | K35: =+I35*20*(100%-25%) -> 2100 | L35: price for collection is written in contract in value 3 000 RON | M35: =+H35/5 -> 1000
A36: PLACENTA | B36: FALSE | C36: FALSE | D36: FALSE | E36: FALSE | F36: TRUE | G36: PL | H36: =+$F$11+H13 -> 4500 | I36: =+$F$12 -> 460 | J36: =+I36*10*(100%-15%) -> 3910 | K36: =+I36*20*(100%-25%) -> 6900 | L36: price for collection is written in contract in value 8 000 RON | M36: =+H36/5 -> 900
A37: PLACENTA | B37: TRUE | C37: FALSE | D37: FALSE | E37: FALSE | F37: TRUE | G37: CB+PL | H37: =+$B$11+$F$11+H13 -> 9000 | I37: =+$B$12+$F$12 -> 850 | J37: =+I37*10*(100%-15%) -> 7225 | K37: =+I37*20*(100%-25%) -> 12750 | M37: =+H37/5 -> 1800
A38: PLACENTA | B38: TRUE | C38: TRUE | D38: FALSE | E38: FALSE | F38: TRUE | G38: CB+PB+PL | H38: =+$B$11+$C$11+$F$11+H13 -> 10000 | I38: =+$B$12+$C$12+$F$12 -> 990 | J38: =+I38*10*(100%-15%) -> 8415 | K38: =+I38*20*(100%-25%) -> 14850 | M38: =+H38/5 -> 2000
A39: PLACENTA | B39: TRUE | C39: FALSE | D39: FALSE | E39: TRUE | F39: TRUE | G39: CB+T(PB)+PL | H39: =+$B$11+$E$11+$F$11+H13 -> 11500 | I39: =+$B$12+$E$12+$F$12 -> 990 | J39: =+I39*10*(100%-15%) -> 8415 | K39: =+I39*20*(100%-25%) -> 14850 | M39: =+H39/5 -> 2300
A40: PLACENTA | B40: FALSE | C40: TRUE | D40: FALSE | E40: FALSE | F40: TRUE | G40: PB+PL | H40: =+$C$11+$F$11+H13 -> 5500 | I40: =+$C$12+$F$12 -> 600 | J40: =+I40*10*(100%-15%) -> 5100 | K40: =+I40*20*(100%-25%) -> 9000 | M40: =+H40/5 -> 1100
A41: PLACENTA | B41: FALSE | C41: TRUE | D41: FALSE | E41: TRUE | F41: TRUE | G41: PB+T(PB)+PL | H41: =+$C$11+$E$11+$F$11+H13 -> 8000 | I41: =+$C$12+$E$12+$F$12 -> 740 | J41: =+I41*10*(100%-15%) -> 6290 | K41: =+I41*20*(100%-25%) -> 11100 | M41: =+H41/5 -> 1600
A42: PLACENTA | B42: FALSE | C42: FALSE | D42: FALSE | E42: TRUE | F42: TRUE | G42: T(PB)+PL | H42: =+$E$11+$F$11+H13 -> 7000 | I42: =+$E$12+$F$12 -> 600 | J42: =+I42*10*(100%-15%) -> 5100 | K42: =+I42*20*(100%-25%) -> 9000 | M42: =+H42/5 -> 1400
...

Sheet HU
A1: HUNGARY
A3: PRICE LIST (from 1.1.2025) | B3: Classic | C3: Premium | D3: Cl.+Tissue | E3: PR.+Tissue | F3: Placenta | J3: CB* | K3: cord blood
B4: =+'COLLECTION PRICE'!C31 -> 560000 | C4: =+'COLLECTION PRICE'!D31 -> 640000 | D4: =+'COLLECTION PRICE'!E31 -> 720000 | E4: =+'COLLECTION PRICE'!F31 -> 840000 | G4: Collection | J4: PB | K4: placental blood
B5: =+'STORAGE PRICE'!C56 -> 32120 | C5: =+'STORAGE PRICE'!D56 -> 41490 | D5: =+'STORAGE PRICE'!E56 -> 40140 | E5: =+'STORAGE PRICE'!F56 -> 49510 | G5: 1 Year storage | J5: T (CB) | K5: cord tissue
B6: =+'STORAGE PRICE'!C57 -> 192720 | C6: =+'STORAGE PRICE'!D57 -> 248940 | D6: =+'STORAGE PRICE'!E57 -> 240840 | E6: =+'STORAGE PRICE'!F57 -> 297060 | G6: 10 Years storage | J6: T (PB) | K6: cord tissue
B7: =+'STORAGE PRICE'!C58 -> 321200 | C7: =+'STORAGE PRICE'!D58 -> 414900 | D7: =+'STORAGE PRICE'!E58 -> 401400 | E7: =+'STORAGE PRICE'!F58 -> 495100 | G7: 20 Years storage | J7: PL | K7: placenta
A9: Failed Collection or Contamination
A10: Product | B10: CB* | C10: PB | D10: T (CB) | E10: T (PB) | F10: PL | H10: Discounted | L10: plati v pripade jednotnej zmluvy CBC AG na odber krv aj tkanivo
A11: Price - collection | B11: =+B4-H13 -> 360000 | C11: =+C4-B4 -> 80000 | D11: =+D4-B4 -> 160000 | E11: =+E4-C4 -> 200000 | G11: Product | H11: price | J11: 40% discount | K11: 50% discount | L11: aktualne sa pouzivaju dve zmluvy: samostatne pre krv (CBC AG) a samostatne pre tkanivo (EC v hodnote 240 000 HUF) | M11: Collection
A12: Price - storage | B12: =+B5 -> 32120 | C12: =+C5-B5 -> 9370 | D12: =+D5-B12 -> 8020 | E12: =+E5-C5 -> 8020 | G12: adjustment | H12: COLLECTION | I12: 1 YEAR STORAGE | J12: 10 YEAR STORAGE | K12: 20 YEAR STORAGE | L12: aktualne sa pouzivanju zlavy 10 rocne skladne 40% a 20 rocne skladne 50% (standard CBC GROUP je 15% a 25%) | M12: in EUR
A13: FLAAT FEE | B13: FALSE | C13: FALSE | D13: FALSE | E13: FALSE | F13: FALSE | G13: ALL | H13: 200000 | M13: =+H13/400 -> 500
A14: Classic | B14: TRUE | C14: FALSE | D14: FALSE | E14: FALSE | F14: FALSE | G14: Classic | H14: =+B4 -> 560000 | I14: =+B5 -> 32120 | J14: =+B6 -> 192720 | K14: =+B7 -> 321200 | M14: =+H14/400 -> 1400
A15: Premium | B15: TRUE | C15: TRUE | D15: FALSE | E15: FALSE | F15: FALSE | G15: Premium | H15: =+C4 -> 640000 | I15: =+C5 -> 41490 | J15: =+C6 -> 248940 | K15: =+C7 -> 414900 | M15: =+H15/400 -> 1600
A16: Premium | B16: TRUE | C16: FALSE | D16: FALSE | E16: FALSE | F16: FALSE | G16: CB | H16: =+$B$11+H13 -> 560000 | I16: =+$B$12 -> 32120 | J16: =+I16*10*(100%-40%) -> 192720 | K16: =+I16*20*(100%-50%) -> 321200 | M16: =+H16/400 -> 1400
A17: Premium | B17: FALSE | C17: TRUE | D17: FALSE | E17: FALSE | F17: FALSE | G17: PB | H17: =+$C$11+H13 -> 280000 | I17: =+$C$12 -> 9370 | J17: =+I17*10*(100%-40%) -> 56220 | K17: =+I17*20*(100%-50%) -> 93700 | M17: =+H17/400 -> 700
A18: Classic+Tissue | B18: TRUE | C18: FALSE | D18: FALSE | E18: FALSE | F18: FALSE | G18: Classic+Tissue | H18: =+D4 -> 720000 | I18: =+D5 -> 40140 | J18: =+D6 -> 240840 | K18: =+D7 -> 401400 | M18: =+H18/400 -> 1800
A19: Classic+Tissue | B19: TRUE | C19: FALSE | D19: FALSE | E19: FALSE | F19: FALSE | G19: CB | H19: =+$B$11+H13 -> 560000 | I19: =+$B$12 -> 32120 | J19: =+I19*10*(100%-40%) -> 192720 | K19: =+I19*20*(100%-50%) -> 321200 | M19: =+H19/400 -> 1400
A20: Classic+Tissue | B20: FALSE | C20: FALSE | D20: TRUE | E20: FALSE | F20: FALSE | G20: T (CB) | H20: =+$D$11+H13 -> 360000 | I20: =+$D$12 -> 8020 | J20: =+I20*10*(100%-40%) -> 48120 | K20: =+I20*20*(100%-50%) -> 80200 | M20: =+H20/400 -> 900
A21: Premium+Tissue | B21: TRUE | C21: TRUE | D21: TRUE | E21: FALSE | F21: FALSE | G21: Premium+Tissue | H21: =+E4 -> 840000 | I21: =+E5 -> 49510 | J21: =+E6 -> 297060 | K21: =+E7 -> 495100 | M21: =+H21/400 -> 2100
A22: Premium+Tissue | B22: TRUE | C22: FALSE | D22: FALSE | E22: FALSE | F22: FALSE | G22: CB | H22: =+$B$11+H13 -> 560000 | I22: =+$B$12 -> 32120 | J22: =+I22*10*(100%-40%) -> 192720 | K22: =+I22*20*(100%-50%) -> 321200 | M22: =+H22/400 -> 1400
A23: Premium+Tissue | B23: TRUE | C23: TRUE | D23: FALSE | E23: TRUE | F23: FALSE | G23: CB + PB | H23: =+$B$11+$C$11+H13 -> 640000 | I23: =+$B$12+$C$12 -> 41490 | J23: =+I23*10*(100%-40%) -> 248940 | K23: =+I23*20*(100%-50%) -> 414900 | M23: =+H23/400 -> 1600
A24: Premium+Tissue | B24: TRUE | C24: FALSE | D24: TRUE | E24: FALSE | F24: FALSE | G24: CB + T (CB) | H24: =+$B$11+$D$11+H13 -> 720000 | I24: =+$B$12+$D$12 -> 40140 | J24: =+I24*10*(100%-40%) -> 240840 | K24: =+I24*20*(100%-50%) -> 401400 | M24: =+H24/400 -> 1800
A25: Premium+Tissue | B25: FALSE | C25: TRUE | D25: FALSE | E25: FALSE | F25: FALSE | G25: PB | H25: =+$C$11+H13 -> 280000 | I25: =+$C$12 -> 9370 | J25: =+I25*10*(100%-40%) -> 56220 | K25: =+I25*20*(100%-50%) -> 93700 | M25: =+H25/400 -> 700
A26: Premium+Tissue | B26: FALSE | C26: TRUE | D26: FALSE | E26: TRUE | F26: FALSE | G26: PB+T (PB) | H26: =+$C$11+$E$11+H13 -> 480000 | I26: =+$C$12+$E$12 -> 17390 | J26: =+I26*10*(100%-40%) -> 104340 | K26: =+I26*20*(100%-50%) -> 173900 | M26: =+H26/400 -> 1200
A27: Premium+Tissue | B27: FALSE | C27: FALSE | D27: FALSE | E27: TRUE | F27: FALSE | G27: T (PB) | H27: =+$E$11+H13 -> 400000 | I27: =+$E$12 -> 8020 | J27: =+I27*10*(100%-40%) -> 48120 | K27: =+I27*20*(100%-50%) -> 80200 | M27: =+H27/400 -> 1000
A28: PLACENTA | B28: TRUE | C28: TRUE | D28: FALSE | E28: TRUE | F28: TRUE | G28: Placenta | H28: =+F4 -> 0 | I28: =+F5 -> 0 | J28: =+F6 -> 0 | K28: =+F7 -> 0 | M28: =+H28/400 -> 0
A29: PLACENTA | B29: TRUE | C29: FALSE | D29: FALSE | E29: FALSE | F29: FALSE | G29: CB | M29: =+H29/400 -> 0
A30: PLACENTA | B30: TRUE | C30: TRUE | D30: FALSE | E30: FALSE | F30: FALSE | G30: CB + PB | M30: =+H30/400 -> 0
A31: PLACENTA | B31: TRUE | C31: TRUE | D31: FALSE | E31: TRUE | F31: FALSE | G31: CB + PB + T (PB) | M31: =+H31/400 -> 0
A32: PLACENTA | B32: TRUE | C32: FALSE | D32: TRUE | E32: FALSE | F32: FALSE | G32: CB + T (CB) | M32: =+H32/400 -> 0
A33: PLACENTA | B33: FALSE | C33: TRUE | D33: FALSE | E33: FALSE | F33: FALSE | G33: PB | M33: =+H33/400 -> 0
A34: PLACENTA | B34: FALSE | C34: TRUE | D34: FALSE | E34: TRUE | F34: FALSE | G34: PB+T (PB) | M34: =+H34/400 -> 0
A35: PLACENTA | B35: FALSE | C35: FALSE | D35: FALSE | E35: TRUE | F35: FALSE | G35: T (PB) | M35: =+H35/400 -> 0
A36: PLACENTA | B36: FALSE | C36: FALSE | D36: FALSE | E36: FALSE | F36: TRUE | G36: PL | M36: =+H36/400 -> 0
A37: PLACENTA | B37: TRUE | C37: FALSE | D37: FALSE | E37: FALSE | F37: TRUE | G37: CB+PL | M37: =+H37/400 -> 0
A38: PLACENTA | B38: TRUE | C38: TRUE | D38: FALSE | E38: FALSE | F38: TRUE | G38: CB+PB+PL | M38: =+H38/400 -> 0
A39: PLACENTA | B39: TRUE | C39: FALSE | D39: FALSE | E39: TRUE | F39: TRUE | G39: CB+T(PB)+PL | M39: =+H39/400 -> 0
A40: PLACENTA | B40: FALSE | C40: TRUE | D40: FALSE | E40: FALSE | F40: TRUE | G40: PB+PL | M40: =+H40/400 -> 0
... A42: PLACENTA | B42: FALSE | C42: FALSE | D42: FALSE | E42: TRUE | F42: TRUE | G42: T(PB)+PL | M42: =+H42/400 -> 0
A43: * collection CB <20ml = discount 160 000 HUF
...

Sheet AT
A1: AUSTRIA
A3: PRICE LIST (from 1.1.2025) | B3: Classic | C3: Premium | D3: Cl.+Tissue | E3: PR.+Tissue | F3: Placenta | J3: CB* | K3: cord blood
B4: =+'COLLECTION PRICE'!C37 -> 1490 | C4: =+'COLLECTION PRICE'!D37 -> 1790 | D4: =+'COLLECTION PRICE'!E37 -> 2190 | E4: =+'COLLECTION PRICE'!F37 -> 2490 | G4: Collection | J4: PB | K4: placental blood
B5: =+'STORAGE PRICE'!C41 -> 67.80253 | C5: =+'STORAGE PRICE'!D41 -> 79.294485 | D5: =+'STORAGE PRICE'!E41 -> 90.786439 | E5: =+'STORAGE PRICE'!F41 -> 102.27839 | G5: 1 Year storage | J5: T (CB) | K5: cord tissue
B6: =+'STORAGE PRICE'!C42 -> 321.77472 | C6: =+'STORAGE PRICE'!D42 -> 376.9361 | D6: =+'STORAGE PRICE'!E42 -> 430.94829 | E6: =+'STORAGE PRICE'!F42 -> 486.10967 | G6: 5 Years storage | J6: T (PB) | K6: cord tissue
B7: =+'STORAGE PRICE'!C43 -> 610.22277 | C7: =+'STORAGE PRICE'!D43 -> 713.65036 | D7: =+'STORAGE PRICE'!E43 -> 817.07795 | E7: =+'STORAGE PRICE'!F43 -> 920.50554 | G7: 10 Years storage | J7: PL | K7: placenta
A9: Failed Collection or Contamination
A10: Product | B10: CB* | C10: PB | D10: T (CB) | E10: T (PB) | F10: PL | H10: Discounted
A11: Price - collection | B11: =+B4-H13 -> 990 | C11: =+C4-B4 -> 300 | D11: =+D4-B4 -> 700 | E11: =+E4-C4 -> 700 | G11: Product | H11: price | J11: 5% discount | K11: 10% discount
A12: Price - storage | B12: =+B5 -> 67.80253 | C12: =+C5-B5 -> 11.491954 | D12: =+D5-B12 -> 22.983909 | E12: =+E5-C5 -> 22.983909 | G12: adjustment | H12: COLLECTION | I12: 1 YEAR STORAGE | J12: 5 YEAR STORAGE | K12: 10 YEAR STORAGE
A13: ALL PRODUCS | B13: FALSE | C13: FALSE | D13: FALSE | E13: FALSE | F13: FALSE | G13: ALL | H13: 500
A14: Classic | B14: TRUE | C14: FALSE | D14: FALSE | E14: FALSE | F14: FALSE | G14: Classic | H14: =+B4 -> 1490 | I14: =+B5 -> 67.80253 | J14: =+B6 -> 321.77472 | K14: =+B7 -> 610.22277
A15: Premium | B15: TRUE | C15: TRUE | D15: FALSE | E15: FALSE | F15: FALSE | G15: Premium | H15: =+C4 -> 1790 | I15: =+C5 -> 79.294485 | J15: =+C6 -> 376.9361 | K15: =+C7 -> 713.65036
A16: Premium | B16: TRUE | C16: FALSE | D16: FALSE | E16: FALSE | F16: FALSE | G16: CB | H16: =+$B$11+H13 -> 1490 | I16: =+$B$12 -> 67.80253 | J16: =+I16*5*(100%-10%) -> 305.11139 | K16: =+I16*10*(100%-15%) -> 576.32151
A17: Premium | B17: FALSE | C17: TRUE | D17: FALSE | E17: FALSE | F17: FALSE | G17: PB | H17: =+$C$11+H13 -> 800 | I17: =+$C$12 -> 11.491954 | J17: =+I17*5*(100%-10%) -> 51.713794 | K17: =+I17*10*(100%-15%) -> 97.681612
A18: Classic+Tissue | B18: TRUE | C18: FALSE | D18: TRUE | E18: FALSE | F18: FALSE | G18: Classic+Tissue | H18: =+D4 -> 2190 | I18: =+D5 -> 90.786439 | J18: =+D6 -> 430.94829 | K18: =+D7 -> 817.07795
A19: Classic+Tissue | B19: TRUE | C19: FALSE | D19: FALSE | E19: FALSE | F19: FALSE | G19: CB | H19: =+$B$11+H13 -> 1490 | I19: =+$B$12 -> 67.80253 | J19: =+I19*5*(100%-10%) -> 305.11139 | K19: =+I19*10*(100%-15%) -> 576.32151
A20: Classic+Tissue | B20: FALSE | C20: FALSE | D20: TRUE | E20: FALSE | F20: FALSE | G20: T (CB) | H20: =+$D$11+H13 -> 1200 | I20: =+$D$12 -> 22.983909 | J20: =+I20*5*(100%-10%) -> 103.42759 | K20: =+I20*10*(100%-15%) -> 195.36322
A21: Premium+Tissue | B21: TRUE | C21: TRUE | D21: TRUE | E21: FALSE | F21: FALSE | G21: Premium+Tissue | H21: =+E4 -> 2490 | I21: =+E5 -> 102.27839 | J21: =+E6 -> 486.10967 | K21: =+E7 -> 920.50554
A22: Premium+Tissue | B22: TRUE | C22: FALSE | D22: FALSE | E22: FALSE | F22: FALSE | G22: CB | H22: =+$B$11+H13 -> 1490 | I22: =+$B$12 -> 67.80253 | J22: =+I22*5*(100%-10%) -> 305.11139 | K22: =+I22*10*(100%-15%) -> 576.32151
A23: Premium+Tissue | B23: TRUE | C23: TRUE | D23: FALSE | E23: FALSE | F23: FALSE | G23: CB + PB | H23: =+$B$11+$C$11+H13 -> 1790 | I23: =+$B$12+$C$12 -> 79.294485 | J23: =+I23*5*(100%-10%) -> 356.82518 | K23: =+I23*10*(100%-15%) -> 674.00312
A24: Premium+Tissue | B24: TRUE | C24: FALSE | D24: TRUE | E24: FALSE | F24: FALSE | G24: CB + T (CB) | H24: =+$B$11+$D$11+H13 -> 2190 | I24: =+$B$12+$D$12 -> 90.786439 | J24: =+I24*5*(100%-10%) -> 408.53898 | K24: =+I24*10*(100%-15%) -> 771.68473
A25: Premium+Tissue | B25: FALSE | C25: TRUE | D25: FALSE | E25: FALSE | F25: FALSE | G25: PB | H25: =+$C$11+H13 -> 800 | I25: =+$C$12 -> 11.491954 | J25: =+I25*5*(100%-10%) -> 51.713794 | K25: =+I25*10*(100%-15%) -> 97.681612
A26: Premium+Tissue | B26: FALSE | C26: TRUE | D26: FALSE | E26: TRUE | F26: FALSE | G26: PB+T (PB) | H26: =+$C$11+$E$11+H13 -> 1500 | I26: =+$C$12+$E$12 -> 34.475863 | J26: =+I26*5*(100%-10%) -> 155.14138 | K26: =+I26*10*(100%-15%) -> 293.04484
A27: Premium+Tissue | B27: FALSE | C27: FALSE | D27: FALSE | E27: TRUE | F27: FALSE | G27: T (PB) | H27: =+$E$11+H13 -> 1200 | I27: =+$E$12 -> 22.983909 | J27: =+I27*5*(100%-10%) -> 103.42759 | K27: =+I27*10*(100%-15%) -> 195.36322
A28: PLACENTA | B28: TRUE | C28: TRUE | D28: FALSE | E28: TRUE | F28: TRUE | G28: Placenta | H28: =+F4 -> 0 | I28: =+F5 -> 0 | J28: =+F6 -> 0 | K28: =+F7 -> 0
A29: PLACENTA | B29: TRUE | C29: FALSE | D29: FALSE | E29: FALSE | F29: FALSE | G29: Classic
A30: PLACENTA | B30: TRUE | C30: TRUE | D30: FALSE | E30: FALSE | F30: FALSE | G30: Premium
A31: PLACENTA | B31: TRUE | C31: TRUE | D31: FALSE | E31: TRUE | F31: FALSE | G31: Premium+Tissue
A32: PLACENTA | B32: TRUE | C32: FALSE | D32: TRUE | E32: FALSE | F32: FALSE | G32: Classic+Tissue
A33: PLACENTA | B33: FALSE | C33: TRUE | D33: FALSE | E33: FALSE | F33: FALSE | G33: PB
A34: PLACENTA | B34: FALSE | C34: TRUE | D34: FALSE | E34: TRUE | F34: FALSE | G34: PB+T (PB)
A35: PLACENTA | B35: FALSE | C35: FALSE | D35: FALSE | E35: TRUE | F35: FALSE | G35: T (PB)
A36: PLACENTA | B36: FALSE | C36: FALSE | D36: FALSE | E36: FALSE | F36: TRUE | G36: PL
A37: PLACENTA | B37: TRUE | C37: FALSE | D37: FALSE | E37: FALSE | F37: TRUE | G37: CB+PL
A38: PLACENTA | B38: TRUE | C38: TRUE | D38: FALSE | E38: FALSE | F38: TRUE | G38: CB+PB+PL
A39: PLACENTA | B39: TRUE | C39: FALSE | D39: FALSE | E39: TRUE | F39: TRUE | G39: CB+T(PB)+PL
A40: PLACENTA | B40: FALSE | C40: TRUE | D40: FALSE | E40: FALSE | F40: TRUE | G40: PB+PL
... A42: PLACENTA | B42: FALSE | C42: FALSE | D42: FALSE | E42: TRUE | F42: TRUE | G42: T(PB)+PL
A43: * collection CB <20ml = discount 400 EUR

Sheet ITA
A1: ITALY
A3: PRICE LIST (from 1.1.2025) | B3: Classic | C3: Premium | D3: Cl.+Tissue | E3: PR.+Tissue | F3: Placenta | J3: CB* | K3: cord blood
B4: =+'COLLECTION PRICE'!C40 -> 1090 | C4: =+'COLLECTION PRICE'!D40 -> 1290 | D4: =+'COLLECTION PRICE'!E40 -> 1390 | E4: =+'COLLECTION PRICE'!F40 -> 1590 | G4: Collection | J4: PB | K4: placental blood
B5: =+'STORAGE PRICE'!C44 -> 65.015013 | C5: =+'STORAGE PRICE'!D44 -> 86.686684 | D5: =+'STORAGE PRICE'!E44 -> 86.686684 | E5: =+'STORAGE PRICE'!F44 -> 92.104602 | G5: 1 Year storage | J5: T (CB) | K5: cord tissue
B6: =+'STORAGE PRICE'!C45 -> 541.79177 | C6: =+'STORAGE PRICE'!D45 -> 639.31429 | D6: =+'STORAGE PRICE'!E45 -> 726.00098 | E6: =+'STORAGE PRICE'!F45 -> 758.50848 | G6: 10 Years storage | J6: T (PB) | K6: cord tissue
B7: =+'STORAGE PRICE'!C46 -> 975.22519 | C7: =+'STORAGE PRICE'!D46 -> 1083.5835 | D7: =+'STORAGE PRICE'!E46 -> 1191.9419 | E7: =+'STORAGE PRICE'!F46 -> 1300.3003 | G7: 20 Years storage | J7: PL | K7: placenta
A9: Failed Collection or Contamination
A10: Product | B10: CB* | C10: PB | D10: T (CB) | E10: T (PB) | F10: PL | H10: Discounted | J10: various % discount | K10: various % discount | L10: absolutne nelogicke ceny a percentualne zlavy pri viacrocnom skladnom
A11: Price - collection | B11: =+B4 -> 1090 | C11: =+C4-B4 -> 200 | D11: =+D4-B4 -> 300 | E11: =+E4-C4 -> 300 | F11: =+F4-E4 -> -1590 | G11: Product | H11: price
A12: Price - storage | B12: =+B5 -> 65.015013 | C12: =+C5-B5 -> 21.671671 | D12: =+D5-B12 -> 21.671671 | E12: =+E5-C5 -> 5.4179177 | F12: =+F5-E5 -> -92.104602 | G12: adjustment | H12: COLLECTION | I12: 1 YEAR STORAGE | J12: 10 YEAR STORAGE | K12: 20 YEAR STORAGE
A13: ALL PRODUCS | B13: FALSE | C13: FALSE | D13: FALSE | E13: FALSE | F13: FALSE | G13: VIP | H13: 1 | L13: stare ceny, nereflektuju aktualnu cenovu politiku CBC GROUP
A14: Classic | B14: TRUE | C14: FALSE | D14: FALSE | E14: FALSE | F14: FALSE | G14: Classic | H14: =+B4 -> 1090 | I14: =+B5 -> 65.015013 | J14: =+B6 -> 541.79177 | K14: =+B7 -> 975.22519
A15: Premium | B15: TRUE | C15: TRUE | D15: FALSE | E15: FALSE | F15: FALSE | G15: Premium | H15: =+C4 -> 1290 | I15: =+C5 -> 86.686684 | J15: =+C6 -> 639.31429 | K15: =+C7 -> 1083.5835
A16: Premium | B16: TRUE | C16: FALSE | D16: FALSE | E16: FALSE | F16: FALSE | G16: CB | H16: =+$B$11 -> 1090 | I16: =+$B$12 -> 65.015013 | J16: =+$J$14 -> 541.79177 | K16: =+$K$14 -> 975.22519
A17: Premium | B17: FALSE | C17: TRUE | D17: FALSE | E17: FALSE | F17: FALSE | G17: PB | H17: =+$C$11 -> 200 | I17: =+$C$12 -> 21.671671 | J17: =+I17*10*85% -> 184.2092 | K17: =+I17*20*75% -> 325.07507
A18: Classic+Tissue | B18: TRUE | C18: FALSE | D18: TRUE | E18: FALSE | F18: FALSE | G18: Classic+Tissue | H18: =+D4 -> 1390 | I18: =+D5 -> 86.686684 | J18: =+D6 -> 726.00098 | K18: =+D7 -> 1191.9419
A19: Classic+Tissue | B19: TRUE | C19: FALSE | D19: FALSE | E19: FALSE | F19: FALSE | G19: CB | H19: =+$B$11 -> 1090 | I19: =+$B$12 -> 65.015013 | J19: =+$J$14 -> 541.79177 | K19: =+$K$14 -> 975.22519
A20: Classic+Tissue | B20: FALSE | C20: FALSE | D20: TRUE | E20: FALSE | F20: FALSE | G20: T (CB) | H20: =+$D$11 -> 300 | I20: =+$D$12 -> 21.671671 | J20: =+I20*10*85% -> 184.2092 | K20: =+I20*20*75% -> 325.07507
A21: Premium+Tissue | B21: TRUE | C21: TRUE | D21: TRUE | E21: FALSE | F21: FALSE | G21: Premium+Tissue | H21: =+E4 -> 1590 | I21: =+E5 -> 92.104602 | J21: =+E6 -> 758.50848 | K21: =+E7 -> 1300.3003
A22: Premium+Tissue | B22: TRUE | C22: FALSE | D22: FALSE | E22: FALSE | F22: FALSE | G22: CB | H22: =+$B$11 -> 1090 | I22: =+$B$12 -> 65.015013 | J22: =+$J$14 -> 541.79177 | K22: =+$K$14 -> 975.22519
A23: Premium+Tissue | B23: TRUE | C23: TRUE | D23: FALSE | E23: FALSE | F23: FALSE | G23: CB + PB | H23: =+$B$11+$C$11 -> 1290 | I23: =+$B$12+$C$12 -> 86.686684 | J23: =+$J$15 -> 639.31429 | K23: =+$K$15 -> 1083.5835
A24: Premium+Tissue | B24: TRUE | C24: FALSE | D24: TRUE | E24: FALSE | F24: FALSE | G24: CB + T (CB) | H24: =+$B$11+$D$11 -> 1390 | I24: =+$B$12+$D$12 -> 86.686684 | J24: =+$J$18 -> 726.00098 | K24: =+$K$18 -> 1191.9419
A25: Premium+Tissue | B25: FALSE | C25: TRUE | D25: FALSE | E25: FALSE | F25: FALSE | G25: PB | H25: =+$C$11 -> 200 | I25: =+$C$12 -> 21.671671 | J25: =+I25*10*85% -> 184.2092 | K25: =+I25*20*75% -> 325.07507
A26: Premium+Tissue | B26: FALSE | C26: TRUE | D26: FALSE | E26: TRUE | F26: FALSE | G26: PB+T (PB) | H26: =+$C$11+$E$11 -> 500 | I26: =+$C$12+$E$12 -> 27.089589 | J26: =+I26*10*85% -> 230.2615 | K26: =+I26*20*75% -> 406.34383
A27: Premium+Tissue | B27: FALSE | C27: FALSE | D27: FALSE | E27: TRUE | F27: FALSE | G27: T (PB) | H27: =+$E$11 -> 300 | I27: =+$E$12 -> 5.4179177 | J27: =+$J$20 -> 184.2092 | K27: =+$K$20 -> 325.07507
A28: PLACENTA | B28: TRUE | C28: TRUE | D28: FALSE | E28: TRUE | F28: TRUE | G28: Placenta | H28: =+F4 -> 0 | I28: =+F5 -> 0 | J28: =+F6 -> 0 | K28: =+F7 -> 0
A29: PLACENTA | B29: TRUE | C29: FALSE | D29: FALSE | E29: FALSE | F29: FALSE | G29: Classic
A30: PLACENTA | B30: TRUE | C30: TRUE | D30: FALSE | E30: FALSE | F30: FALSE | G30: Premium
A31: PLACENTA | B31: TRUE | C31: TRUE | D31: FALSE | E31: TRUE | F31: FALSE | G31: Premium+Tissue
A32: PLACENTA | B32: TRUE | C32: FALSE | D32: TRUE | E32: FALSE | F32: FALSE | G32: Classic+Tissue
A33: PLACENTA | B33: FALSE | C33: TRUE | D33: FALSE | E33: FALSE | F33: FALSE | G33: PB
A34: PLACENTA | B34: FALSE | C34: TRUE | D34: FALSE | E34: TRUE | F34: FALSE | G34: PB+T (PB)
A35: PLACENTA | B35: FALSE | C35: FALSE | D35: FALSE | E35: TRUE | F35: FALSE | G35: T (PB)
A36: PLACENTA | B36: FALSE | C36: FALSE | D36: FALSE | E36: FALSE | F36: TRUE | G36: PL
A37: PLACENTA | B37: TRUE | C37: FALSE | D37: FALSE | E37: FALSE | F37: TRUE | G37: CB+PL
A38: PLACENTA | B38: TRUE | C38: TRUE | D38: FALSE | E38: FALSE | F38: TRUE | G38: CB+PB+PL
A39: PLACENTA | B39: TRUE | C39: FALSE | D39: FALSE | E39: TRUE | F39: TRUE | G39: CB+T(PB)+PL
A40: PLACENTA | B40: FALSE | C40: TRUE | D40: FALSE | E40: FALSE | F40: TRUE | G40: PB+PL
... A42: PLACENTA | B42: FALSE | C42: FALSE | D42: FALSE | E42: TRUE | F42: TRUE | G42: T(PB)+PL
A43: * collection CB <20ml = discount 400 EUR

Sheet cost
B3: SK | L3: RO | V3: CZ | AF3: HU | AP3: AT | AW3: ITA
B4: Classic | C4: Premium | D4: CB+T | E4: PB+T | F4: PB+T+P | H4: PB | I4: T | J4: PL | L4: Classic | M4: Premium | N4: CB+T | O4: PB+T | P4: PB+T+P | R4: PB | S4: T | T4: PL | V4: Classic | W4: Premium | X4: CB+T | Y4: PB+T | Z4: PB+T+P | AB4: PB | AC4: T | AD4: PL | AF4: Classic | AG4: Premium | AH4: CB+T | AI4: PB+T | AJ4: PB+T+P | AL4: PB | AM4: T | AN4: PL | AP4: Classic | AQ4: Premium | AR4: CB+T | AS4: PB+T | AT4: PB+T+P | AW4: Classic | AX4: Premium | AY4: CB+T | AZ4: PB+T | BA4: PB+T+P
A5: Gross revenue - new prices | B5: 1400 | C5: 1600 | D5: 1800 | E5: 2100 | F5: 2500 | H5: =+SK!H17 -> 700 | I5: =+SK!H20 -> 900 | J5: =+SK!H36 -> 900 | L5: 1400 | M5: 1600 | N5: 1800 | O5: 2100 | P5: 2500 | R5: =+RO!H17/5 -> 700 | S5: =+RO!H20/5 -> 900 | T5: =+RO!H36/5 -> 900 | V5: 1400 | W5: 1600 | X5: 1800 | Y5: 2100 | Z5: 2500 | AB5: =+CZ!H17/25 -> 700 | AC5: =+CZ!H20/25 -> 900 | AD5: =+CZ!H36/25 -> 900 | AF5: 1400 | AG5: 1600 | AH5: 1800 | AI5: 2100 | AL5: =+HU!H17/400 -> 700 | AM5: =+HU!H20/400 -> 900 | AP5: 1490 | AQ5: 1790 | AR5: 2190 | AS5: 2490 | AW5: 1090 | AX5: 1290 | AY5: 1390 | AZ5: 1590
